Workbook

Sheet Trading Steps
A1: Investment Size | B1: Interest Rate | C1: after 6.28 % profit value | D1: Profit amount | E1: Brokerage plus charges Both Side | F1: Pledge Charges with GST both side | G1: Estimated Interest Charges | H1: Remain Profit | I1: Income Tax | J1: Profit after tax | K1: Self Dividend | L1: Growth Amount after Tax and Dividend | M1: 3 in 1 step
A2: 15000 | B2: 0.0985 | C2: =A2*1.0628 -> 15942 | D2: =C2-A2 -> 942 | E2: =((A2+C2)*0.0012) -> 37.1304 | F2: =(25*2)*1.18 -> 59 | G2: =A2 * (17/30) * 8.5 * (B2 / 365 * 7) -> 136.48322 | H2: =D2-E2-F2-G2 -> 709.38638 | I2: =(H2*0.2)*1.04 -> 147.55237 | J2: =H2-I2 -> 561.83401 | K2: =J2*0.5 -> 280.91701 | L2: =J2-K2 -> 280.91701 | M2: =(A2+A3+A4)/3 -> 15282.817
A3: =A2+L2 -> 15280.917 | B3: =B2 -> 0.0985 | C3: =A3*1.0628 -> 16240.559 | D3: =C3-A3 -> 959.64159 | E3: =((A3+C3)*0.0012) -> 37.825771 | F3: =(25*2)*1.18 -> 59 | G3: =A3 * (17/30) * 8.5 * (B3 / 365 * 7) -> 139.03925 | H3: =D3-E3-F3-G3 -> 723.77657 | I3: =(H3*0.2)*1.04 -> 150.54553 | J3: =H3-I3 -> 573.23104 | K3: =J3*0.5 -> 286.61552 | L3: =J3-K3 -> 286.61552
A4: =A3+L3 -> 15567.533 | B4: =B3 -> 0.0985 | C4: =A4*1.0628 -> 16545.174 | D4: =C4-A4 -> 977.64104 | E4: =((A4+C4)*0.0012) -> 38.535247 | F4: =(25*2)*1.18 -> 59 | G4: =A4 * (17/30) * 8.5 * (B4 / 365 * 7) -> 141.64713 | H4: =D4-E4-F4-G4 -> 738.45867 | I4: =(H4*0.2)*1.04 -> 153.5994 | J4: =H4-I4 -> 584.85926 | K4: =J4*0.5 -> 292.42963 | L4: =J4-K4 -> 292.42963
A5: =A4+L4 -> 15859.962 | B5: =B4 -> 0.0985 | C5: =A5*1.0628 -> 16855.968 | D5: =C5-A5 -> 996.00562 | E5: =((A5+C5)*0.0012) -> 39.259116 | F5: =(25*2)*1.18 -> 59 | G5: =A5 * (17/30) * 8.5 * (B5 / 365 * 7) -> 144.30791 | H5: =D5-E5-F5-G5 -> 753.43859 | I5: =(H5*0.2)*1.04 -> 156.71523 | J5: =H5-I5 -> 596.72337 | K5: =J5*0.5 -> 298.36168 | L5: =J5-K5 -> 298.36168 | M5: =(A5+A6+A7)/3 -> 16160.341
A6: =A5+L5 -> 16158.324 | B6: =B5 -> 0.0985 | C6: =A6*1.0628 -> 17173.067 | D6: =C6-A6 -> 1014.7427 | E6: =((A6+C6)*0.0012) -> 39.997669 | F6: =(25*2)*1.18 -> 59 | G6: =A6 * (17/30) * 8.5 * (B6 / 365 * 7) -> 147.02267 | H6: =D6-E6-F6-G6 -> 768.7224 | I6: =(H6*0.2)*1.04 -> 159.89426 | J6: =H6-I6 -> 608.82814 | K6: =J6*0.5 -> 304.41407 | L6: =J6-K6 -> 304.41407
A7: =A6+L6 -> 16462.738 | B7: =B6 -> 0.0985 | C7: =A7*1.0628 -> 17496.598 | D7: =C7-A7 -> 1033.8599 | E7: =((A7+C7)*0.0012) -> 40.751203 | F7: =(25*2)*1.18 -> 59 | G7: =A7 * (17/30) * 8.5 * (B7 / 365 * 7) -> 149.7925 | H7: =D7-E7-F7-G7 -> 784.31624 | I7: =(H7*0.2)*1.04 -> 163.13778 | J7: =H7-I7 -> 621.17846 | K7: =J7*0.5 -> 310.58923 | L7: =J7-K7 -> 310.58923
A8: =A7+L7 -> 16773.327 | B8: =B7 -> 0.0985 | C8: =A8*1.0628 -> 17826.692 | D8: =C8-A8 -> 1053.3649 | E8: =((A8+C8)*0.0012) -> 41.520023 | F8: =(25*2)*1.18 -> 59 | G8: =A8 * (17/30) * 8.5 * (B8 / 365 * 7) -> 152.61851 | H8: =D8-E8-F8-G8 -> 800.22641 | I8: =(H8*0.2)*1.04 -> 166.44709 | J8: =H8-I8 -> 633.77932 | K8: =J8*0.5 -> 316.88966 | L8: =J8-K8 -> 316.88966 | M8: =(A8+A9+A10)/3 -> 17092.36
A9: =A8+L8 -> 17090.217 | B9: =B8 -> 0.0985 | C9: =A9*1.0628 -> 18163.482 | D9: =C9-A9 -> 1073.2656 | E9: =((A9+C9)*0.0012) -> 42.304439 | F9: =(25*2)*1.18 -> 59 | G9: =A9 * (17/30) * 8.5 * (B9 / 365 * 7) -> 155.50185 | H9: =D9-E9-F9-G9 -> 816.45932 | I9: =(H9*0.2)*1.04 -> 169.82354 | J9: =H9-I9 -> 646.63578 | K9: =J9*0.5 -> 323.31789 | L9: =J9-K9 -> 323.31789
A10: =A9+L9 -> 17413.535 | B10: =B9 -> 0.0985 | C10: =A10*1.0628 -> 18507.105 | D10: =C10-A10 -> 1093.57 | E10: =((A10+C10)*0.0012) -> 43.104767 | F10: =(25*2)*1.18 -> 59 | G10: =A10 * (17/30) * 8.5 * (B10 / 365 * 7) -> 158.44368 | H10: =D10-E10-F10-G10 -> 833.02153 | I10: =(H10*0.2)*1.04 -> 173.26848 | J10: =H10-I10 -> 659.75305 | K10: =J10*0.5 -> 329.87652 | L10: =J10-K10 -> 329.87652
A11: =A10+L10 -> 17743.411 | B11: =B10 -> 0.0985 | C11: =A11*1.0628 -> 18857.697 | D11: =C11-A11 -> 1114.2862 | E11: =((A11+C11)*0.0012) -> 43.92133 | F11: =(25*2)*1.18 -> 59 | G11: =A11 * (17/30) * 8.5 * (B11 / 365 * 7) -> 161.44519 | H11: =D11-E11-F11-G11 -> 849.9197 | I11: =(H11*0.2)*1.04 -> 176.7833 | J11: =H11-I11 -> 673.1364 | K11: =J11*0.5 -> 336.5682 | L11: =J11-K11 -> 336.5682 | M11: =(A11+A12+A13)/3 -> 18082.255
A12: =A11+L11 -> 18079.979 | B12: =B11 -> 0.0985 | C12: =A12*1.0628 -> 19215.402 | D12: =C12-A12 -> 1135.4227 | E12: =((A12+C12)*0.0012) -> 44.754458 | F12: =(25*2)*1.18 -> 59 | G12: =A12 * (17/30) * 8.5 * (B12 / 365 * 7) -> 164.50759 | H12: =D12-E12-F12-G12 -> 867.16066 | I12: =(H12*0.2)*1.04 -> 180.36942 | J12: =H12-I12 -> 686.79125 | K12: =J12*0.5 -> 343.39562 | L12: =J12-K12 -> 343.39562
A13: =A12+L12 -> 18423.375 | B13: =B12 -> 0.0985 | C13: =A13*1.0628 -> 19580.363 | D13: =C13-A13 -> 1156.988 | E13: =((A13+C13)*0.0012) -> 45.604486 | F13: =(25*2)*1.18 -> 59 | G13: =A13 * (17/30) * 8.5 * (B13 / 365 * 7) -> 167.6321 | H13: =D13-E13-F13-G13 -> 884.75136 | I13: =(H13*0.2)*1.04 -> 184.02828 | J13: =H13-I13 -> 700.72308 | K13: =J13*0.5 -> 350.36154 | L13: =J13-K13 -> 350.36154
A14: =A13+L13 -> 18773.737 | B14: =B13 -> 0.0985 | C14: =A14*1.0628 -> 19952.727 | D14: =C14-A14 -> 1178.9907 | E14: =((A14+C14)*0.0012) -> 46.471757 | F14: =(25*2)*1.18 -> 59 | G14: =A14 * (17/30) * 8.5 * (B14 / 365 * 7) -> 170.82 | H14: =D14-E14-F14-G14 -> 902.6989 | I14: =(H14*0.2)*1.04 -> 187.76137 | J14: =H14-I14 -> 714.93753 | K14: =J14*0.5 -> 357.46876 | L14: =J14-K14 -> 357.46876 | M14: =(A14+A15+A16)/3 -> 19133.622
A15: =A14+L14 -> 19131.205 | B15: =B14 -> 0.0985 | C15: =A15*1.0628 -> 20332.645 | D15: =C15-A15 -> 1201.4397 | E15: =((A15+C15)*0.0012) -> 47.35662 | F15: =(25*2)*1.18 -> 59 | G15: =A15 * (17/30) * 8.5 * (B15 / 365 * 7) -> 174.07257 | H15: =D15-E15-F15-G15 -> 921.01051 | I15: =(H15*0.2)*1.04 -> 191.57019 | J15: =H15-I15 -> 729.44032 | K15: =J15*0.5 -> 364.72016 | L15: =J15-K15 -> 364.72016
A16: =A15+L15 -> 19495.926 | B16: =B15 -> 0.0985 | C16: =A16*1.0628 -> 20720.27 | D16: =C16-A16 -> 1224.3441 | E16: =((A16+C16)*0.0012) -> 48.259434 | F16: =(25*2)*1.18 -> 59 | G16: =A16 * (17/30) * 8.5 * (B16 / 365 * 7) -> 177.39111 | H16: =D16-E16-F16-G16 -> 939.69358 | I16: =(H16*0.2)*1.04 -> 195.45626 | J16: =H16-I16 -> 744.23731 | K16: =J16*0.5 -> 372.11866 | L16: =J16-K16 -> 372.11866
A17: =A16+L16 -> 19868.044 | B17: =B16 -> 0.0985 | C17: =A17*1.0628 -> 21115.757 | D17: =C17-A17 -> 1247.7132 | E17: =((A17+C17)*0.0012) -> 49.180562 | F17: =(25*2)*1.18 -> 59 | G17: =A17 * (17/30) * 8.5 * (B17 / 365 * 7) -> 180.77698 | H17: =D17-E17-F17-G17 -> 958.75564 | I17: =(H17*0.2)*1.04 -> 199.42117 | J17: =H17-I17 -> 759.33446 | K17: =J17*0.5 -> 379.66723 | L17: =J17-K17 -> 379.66723 | M17: =(A17+A18+A19)/3 -> 20250.279
A18: =A17+L17 -> 20247.711 | B18: =B17 -> 0.0985 | C18: =A18*1.0628 -> 21519.268 | D18: =C18-A18 -> 1271.5563 | E18: =((A18+C18)*0.0012) -> 50.120375 | F18: =(25*2)*1.18 -> 59 | G18: =A18 * (17/30) * 8.5 * (B18 / 365 * 7) -> 184.23152 | H18: =D18-E18-F18-G18 -> 978.20438 | I18: =(H18*0.2)*1.04 -> 203.46651 | J18: =H18-I18 -> 774.73787 | K18: =J18*0.5 -> 387.36893 | L18: =J18-K18 -> 387.36893
A19: =A18+L18 -> 20635.08 | B19: =B18 -> 0.0985 | C19: =A19*1.0628 -> 21930.963 | D19: =C19-A19 -> 1295.883 | E19: =((A19+C19)*0.0012) -> 51.079252 | F19: =(25*2)*1.18 -> 59 | G19: =A19 * (17/30) * 8.5 * (B19 / 365 * 7) -> 187.75615 | H19: =D19-E19-F19-G19 -> 998.04765 | I19: =(H19*0.2)*1.04 -> 207.59391 | J19: =H19-I19 -> 790.45374 | K19: =J19*0.5 -> 395.22687 | L19: =J19-K19 -> 395.22687
A20: =A19+L19 -> 21030.307 | B20: =B19 -> 0.0985 | C20: =A20*1.0628 -> 22351.01 | D20: =C20-A20 -> 1320.7033 | E20: =((A20+C20)*0.0012) -> 52.057581 | F20: =(25*2)*1.18 -> 59 | G20: =A20 * (17/30) * 8.5 * (B20 / 365 * 7) -> 191.35227 | H20: =D20-E20-F20-G20 -> 1018.2934 | I20: =(H20*0.2)*1.04 -> 211.80504 | J20: =H20-I20 -> 806.48841 | K20: =J20*0.5 -> 403.2442 | L20: =J20-K20 -> 403.2442 | M20: =(A20+A21+A22)/3 -> 21436.278
A21: =A20+L20 -> 21433.551 | B21: =B20 -> 0.0985 | C21: =A21*1.0628 -> 22779.578 | D21: =C21-A21 -> 1346.027 | E21: =((A21+C21)*0.0012) -> 53.055756 | F21: =(25*2)*1.18 -> 59 | G21: =A21 * (17/30) * 8.5 * (B21 / 365 * 7) -> 195.02134 | H21: =D21-E21-F21-G21 -> 1038.9499 | I21: =(H21*0.2)*1.04 -> 216.10159 | J21: =H21-I21 -> 822.84835 | K21: =J21*0.5 -> 411.42417 | L21: =J21-K21 -> 411.42417
A22: =A21+L21 -> 21844.976 | B22: =B21 -> 0.0985 | C22: =A22*1.0628 -> 23216.84 | D22: =C22-A22 -> 1371.8645 | E22: =((A22+C22)*0.0012) -> 54.074179 | F22: =(25*2)*1.18 -> 59 | G22: =A22 * (17/30) * 8.5 * (B22 / 365 * 7) -> 198.76484 | H22: =D22-E22-F22-G22 -> 1060.0254 | I22: =(H22*0.2)*1.04 -> 220.48529 | J22: =H22-I22 -> 839.54015 | K22: =J22*0.5 -> 419.77008 | L22: =J22-K22 -> 419.77008
A23: =A22+L22 -> 22264.746 | B23: =B22 -> 0.0985 | C23: =A23*1.0628 -> 23662.972 | D23: =C23-A23 -> 1398.226 | E23: =((A23+C23)*0.0012) -> 55.113261 | F23: =(25*2)*1.18 -> 59 | G23: =A23 * (17/30) * 8.5 * (B23 / 365 * 7) -> 202.58428 | H23: =D23-E23-F23-G23 -> 1081.5285 | I23: =(H23*0.2)*1.04 -> 224.95793 | J23: =H23-I23 -> 856.57056 | K23: =J23*0.5 -> 428.28528 | L23: =J23-K23 -> 428.28528 | M23: =(A23+A24+A25)/3 -> 22695.927
A24: =A23+L23 -> 22693.031 | B24: =B23 -> 0.0985 | C24: =A24*1.0628 -> 24118.153 | D24: =C24-A24 -> 1425.1223 | E24: =((A24+C24)*0.0012) -> 56.173421 | F24: =(25*2)*1.18 -> 59 | G24: =A24 * (17/30) * 8.5 * (B24 / 365 * 7) -> 206.48119 | H24: =D24-E24-F24-G24 -> 1103.4677 | I24: =(H24*0.2)*1.04 -> 229.52129 | J24: =H24-I24 -> 873.94644 | K24: =J24*0.5 -> 436.97322 | L24: =J24-K24 -> 436.97322
A25: =A24+L24 -> 23130.004 | B25: =B24 -> 0.0985 | C25: =A25*1.0628 -> 24582.568 | D25: =C25-A25 -> 1452.5643 | E25: =((A25+C25)*0.0012) -> 57.255087 | F25: =(25*2)*1.18 -> 59 | G25: =A25 * (17/30) * 8.5 * (B25 / 365 * 7) -> 210.45716 | H25: =D25-E25-F25-G25 -> 1125.852 | I25: =(H25*0.2)*1.04 -> 234.17722 | J25: =H25-I25 -> 891.67479 | K25: =J25*0.5 -> 445.8374 | L25: =J25-K25 -> 445.8374
A26: =A25+L25 -> 23575.842 | B26: =B25 -> 0.0985 | C26: =A26*1.0628 -> 25056.404 | D26: =C26-A26 -> 1480.5628 | E26: =((A26+C26)*0.0012) -> 58.358695 | F26: =(25*2)*1.18 -> 59 | G26: =A26 * (17/30) * 8.5 * (B26 / 365 * 7) -> 214.51378 | H26: =D26-E26-F26-G26 -> 1148.6904 | I26: =(H26*0.2)*1.04 -> 238.9276 | J26: =H26-I26 -> 909.76277 | K26: =J26*0.5 -> 454.88139 | L26: =J26-K26 -> 454.88139 | M26: =(A26+A27+A28)/3 -> 24033.799
A27: =A26+L26 -> 24030.723 | B27: =B26 -> 0.0985 | C27: =A27*1.0628 -> 25539.852 | D27: =C27-A27 -> 1509.1294 | E27: =((A27+C27)*0.0012) -> 59.48469 | F27: =(25*2)*1.18 -> 59 | G27: =A27 * (17/30) * 8.5 * (B27 / 365 * 7) -> 218.6527 | H27: =D27-E27-F27-G27 -> 1171.992 | I27: =(H27*0.2)*1.04 -> 243.77434 | J27: =H27-I27 -> 928.21768 | K27: =J27*0.5 -> 464.10884 | L27: =J27-K27 -> 464.10884
A28: =A27+L27 -> 24494.832 | B28: =B27 -> 0.0985 | C28: =A28*1.0628 -> 26033.107 | D28: =C28-A28 -> 1538.2754 | E28: =((A28+C28)*0.0012) -> 60.633527 | F28: =(25*2)*1.18 -> 59 | G28: =A28 * (17/30) * 8.5 * (B28 / 365 * 7) -> 222.87557 | H28: =D28-E28-F28-G28 -> 1195.7663 | I28: =(H28*0.2)*1.04 -> 248.7194 | J28: =H28-I28 -> 947.04694 | K28: =J28*0.5 -> 473.52347 | L28: =J28-K28 -> 473.52347
A29: =A28+L28 -> 24968.355 | B29: =B28 -> 0.0985 | C29: =A29*1.0628 -> 26536.368 | D29: =C29-A29 -> 1568.0127 | E29: =((A29+C29)*0.0012) -> 61.805668 | F29: =(25*2)*1.18 -> 59 | G29: =A29 * (17/30) * 8.5 * (B29 / 365 * 7) -> 227.1841 | H29: =D29-E29-F29-G29 -> 1220.0229 | I29: =(H29*0.2)*1.04 -> 253.76477 | J29: =H29-I29 -> 966.25817 | K29: =J29*0.5 -> 483.12908 | L29: =J29-K29 -> 483.12908 | M29: =(A29+A30+A31)/3 -> 25454.751
A30: =A29+L29 -> 25451.484 | B30: =B29 -> 0.0985 | C30: =A30*1.0628 -> 27049.838 | D30: =C30-A30 -> 1598.3532 | E30: =((A30+C30)*0.0012) -> 63.001586 | F30: =(25*2)*1.18 -> 59 | G30: =A30 * (17/30) * 8.5 * (B30 / 365 * 7) -> 231.58003 | H30: =D30-E30-F30-G30 -> 1244.7716 | I30: =(H30*0.2)*1.04 -> 258.91249 | J30: =H30-I30 -> 985.8591 | K30: =J30*0.5 -> 492.92955 | L30: =J30-K30 -> 492.92955
A31: =A30+L30 -> 25944.414 | B31: =B30 -> 0.0985 | C31: =A31*1.0628 -> 27573.723 | D31: =C31-A31 -> 1629.3092 | E31: =((A31+C31)*0.0012) -> 64.221764 | F31: =(25*2)*1.18 -> 59 | G31: =A31 * (17/30) * 8.5 * (B31 / 365 * 7) -> 236.06514 | H31: =D31-E31-F31-G31 -> 1270.0223 | I31: =(H31*0.2)*1.04 -> 264.16464 | J31: =H31-I31 -> 1005.8577 | K31: =J31*0.5 -> 502.92883 | L31: =J31-K31 -> 502.92883
A32: =A31+L31 -> 26447.343 | B32: =B31 -> 0.0985 | C32: =A32*1.0628 -> 28108.236 | D32: =C32-A32 -> 1660.8931 | E32: =((A32+C32)*0.0012) -> 65.466694 | F32: =(25*2)*1.18 -> 59 | G32: =A32 * (17/30) * 8.5 * (B32 / 365 * 7) -> 240.64123 | H32: =D32-E32-F32-G32 -> 1295.7852 | I32: =(H32*0.2)*1.04 -> 269.52332 | J32: =H32-I32 -> 1026.2619 | K32: =J32*0.5 -> 513.13094 | L32: =J32-K32 -> 513.13094 | M32: =(A32+A33+A34)/3 -> 26963.943
A33: =A32+L32 -> 26960.474 | B33: =B32 -> 0.0985 | C33: =A33*1.0628 -> 28653.591 | D33: =C33-A33 -> 1693.1177 | E33: =((A33+C33)*0.0012) -> 66.736878 | F33: =(25*2)*1.18 -> 59 | G33: =A33 * (17/30) * 8.5 * (B33 / 365 * 7) -> 245.31015 | H33: =D33-E33-F33-G33 -> 1322.0707 | I33: =(H33*0.2)*1.04 -> 274.99071 | J33: =H33-I33 -> 1047.08 | K33: =J33*0.5 -> 523.54 | L33: =J33-K33 -> 523.54
A34: =A33+L33 -> 27484.014 | B34: =B33 -> 0.0985 | C34: =A34*1.0628 -> 29210.01 | D34: =C34-A34 -> 1725.9961 | E34: =((A34+C34)*0.0012) -> 68.032828 | F34: =(25*2)*1.18 -> 59 | G34: =A34 * (17/30) * 8.5 * (B34 / 365 * 7) -> 250.07378 | H34: =D34-E34-F34-G34 -> 1348.8895 | I34: =(H34*0.2)*1.04 -> 280.56901 | J34: =H34-I34 -> 1068.3204 | K34: =J34*0.5 -> 534.16022 | L34: =J34-K34 -> 534.16022
A35: =A34+L34 -> 28018.174 | B35: =B34 -> 0.0985 | C35: =A35*1.0628 -> 29777.715 | D35: =C35-A35 -> 1759.5413 | E35: =((A35+C35)*0.0012) -> 69.355067 | F35: =(25*2)*1.18 -> 59 | G35: =A35 * (17/30) * 8.5 * (B35 / 365 * 7) -> 254.93404 | H35: =D35-E35-F35-G35 -> 1376.2522 | I35: =(H35*0.2)*1.04 -> 286.26046 | J35: =H35-I35 -> 1089.9918 | K35: =J35*0.5 -> 544.99588 | L35: =J35-K35 -> 544.99588 | M35: =(A35+A36+A37)/3 -> 28566.855
A36: =A35+L35 -> 28563.17 | B36: =B35 -> 0.0985 | C36: =A36*1.0628 -> 30356.937 | D36: =C36-A36 -> 1793.7671 | E36: =((A36+C36)*0.0012) -> 70.704128 | F36: =(25*2)*1.18 -> 59 | G36: =A36 * (17/30) * 8.5 * (B36 / 365 * 7) -> 259.89289 | H36: =D36-E36-F36-G36 -> 1404.17 | I36: =(H36*0.2)*1.04 -> 292.06737 | J36: =H36-I36 -> 1112.1027 | K36: =J36*0.5 -> 556.05134 | L36: =J36-K36 -> 556.05134
A37: =A36+L36 -> 29119.221 | B37: =B36 -> 0.0985 | C37: =A37*1.0628 -> 30947.908 | D37: =C37-A37 -> 1828.6871 | E37: =((A37+C37)*0.0012) -> 72.080555 | F37: =(25*2)*1.18 -> 59 | G37: =A37 * (17/30) * 8.5 * (B37 / 365 * 7) -> 264.95234 | H37: =D37-E37-F37-G37 -> 1432.6542 | I37: =(H37*0.2)*1.04 -> 297.99207 | J37: =H37-I37 -> 1134.6621 | K37: =J37*0.5 -> 567.33106 | L37: =J37-K37 -> 567.33106
A38: =A37+L37 -> 29686.552 | B38: =B37 -> 0.0985 | C38: =A38*1.0628 -> 31550.868 | D38: =C38-A38 -> 1864.3155 | E38: =((A38+C38)*0.0012) -> 73.484904 | F38: =(25*2)*1.18 -> 59 | G38: =A38 * (17/30) * 8.5 * (B38 / 365 * 7) -> 270.11441 | H38: =D38-E38-F38-G38 -> 1461.7162 | I38: =(H38*0.2)*1.04 -> 304.03696 | J38: =H38-I38 -> 1157.6792 | K38: =J38*0.5 -> 578.8396 | L38: =J38-K38 -> 578.8396 | M38: =(A38+A39+A40)/3 -> 30269.306
A39: =A38+L38 -> 30265.392 | B39: =B38 -> 0.0985 | C39: =A39*1.0628 -> 32166.058 | D39: =C39-A39 -> 1900.6666 | E39: =((A39+C39)*0.0012) -> 74.91774 | F39: =(25*2)*1.18 -> 59 | G39: =A39 * (17/30) * 8.5 * (B39 / 365 * 7) -> 275.38121 | H39: =D39-E39-F39-G39 -> 1491.3677 | I39: =(H39*0.2)*1.04 -> 310.20447 | J39: =H39-I39 -> 1181.1632 | K39: =J39*0.5 -> 590.58159 | L39: =J39-K39 -> 590.58159
A40: =A39+L39 -> 30855.973 | B40: =B39 -> 0.0985 | C40: =A40*1.0628 -> 32793.728 | D40: =C40-A40 -> 1937.7551 | E40: =((A40+C40)*0.0012) -> 76.379642 | F40: =(25*2)*1.18 -> 59 | G40: =A40 * (17/30) * 8.5 * (B40 / 365 * 7) -> 280.75484 | H40: =D40-E40-F40-G40 -> 1521.6206 | I40: =(H40*0.2)*1.04 -> 316.49709 | J40: =H40-I40 -> 1205.1236 | K40: =J40*0.5 -> 602.56178 | L40: =J40-K40 -> 602.56178
...

Sheet Force and Reserve Force
B1: 1 | E1: 2 | H1: 3 | K1: 4 | N1: 5 | Q1: 6 | T1: 7 | W1: 8 | Z1: 9 | AC1: 10 | AF1: 11 | AI1: 12 | AL1: 13 | AO1: 14 | AR1: 15 | AU1: 16 | AX1: 17
A2: Step | B2: Amount | C2: Stock | D2: F/RF | E2: Amount | F2: Stock | G2: F/RF | H2: Amount | I2: Stock | J2: F/RF | K2: Amount | L2: Stock | M2: F/RF | N2: Amount | O2: Stock | P2: F/RF | Q2: Amount | R2: Stock | S2: F/RF | T2: Amount | U2: Stock | V2: F/RF | W2: Amount | X2: Stock | Y2: F/RF
A3: 1 | B3: ='Trading Steps'!M2 -> 15282.817 | C3: ONGC | D3: F | E3: =B3 -> 15282.817 | F3: BEL | G3: F | H3: =E3 -> 15282.817 | I3: MAHABANK | J3: F
A4: 2 | B4: ='Trading Steps'!M5 -> 16160.341 | C4: POWERGRID | D4: RF | E4: =B4 -> 16160.341 | F4: PETRONET | G4: F | H4: =E4 -> 16160.341 | I4: NLC INDIA | J4: F | K4: =H4 -> 16160.341 | L4: PFC | M4: F | N4: =K4 -> 16160.341 | O4: Apolo Hospital | P4: RF | Q4: =N4 -> 16160.341 | R4: Torrent Power | S4: RF | T4: =Q4 -> 16160.341 | U4: Sun Pharma | V4: RF | W4: =T4 -> 16160.341 | X4: IRB INFRA | Y4: RF
A5: 3 | B5: ='Trading Steps'!M8 -> 17092.36 | C5: NHPC | D5: RF | E5: =B5 -> 17092.36 | F5: HUDCO | G5: F | H5: =E5 -> 17092.36 | I5: GICRE | J5: RF | K5: =H5 -> 17092.36 | L5: NYKAA | M5: RF | N5: =K5 -> 17092.36 | O5: YES BANK | P5: F | Q5: =N5 -> 17092.36 | R5: ATGL | S5: F
A6: 4 | B6: ='Trading Steps'!M11 -> 18082.255 | C6: PREMIRENE | D6: F | E6: =B6 -> 18082.255 | F6: MOTILALOFS | G6: F | H6: =E6 -> 18082.255 | I6: Dr Reddy | J6: RF | K6: =H6 -> 18082.255 | L6: ASIAN PAINT | M6: RF | N6: =K6 -> 18082.255 | O6: SUZLON | P6: RF | Q6: =N6 -> 18082.255 | R6: TMPV | S6: RF | T6: =Q6 -> 18082.255 | U6: FORTIES | V6: RF | W6: =T6 -> 18082.255 | X6: MANKIND | Y6: F
A7: 5 | B7: ='Trading Steps'!M14 -> 19133.622 | C7: IDFCFRSTB | D7: F | E7: =B7 -> 19133.622 | F7: AXISBANK | G7: RF | H7: =E7 -> 19133.622 | I7: Gail | J7: RF | K7: =H7 -> 19133.622 | L7: INDHOTEL | M7: RF | N7: =K7 -> 19133.622 | O7: HUDCO | P7: RF | Q7: =N7 -> 19133.622 | R7: ETERNAL | S7: RF | T7: =Q7 -> 19133.622 | U7: REC Ltd | V7: RF | W7: =T7 -> 19133.622 | X7: BAJAJFIN | Y7: RF | Z7: =W7 -> 19133.622 | AA7: MAXHEALTH | AB7: RF | AC7: =Z7 -> 19133.622 | AD7: LIC | AE7: RF | AF7: =AC7 -> 19133.622 | AG7: HDFCAMC | AH7: RF | AI7: =AF7 -> 19133.622 | AJ7: ENDURANCE | AK7: RF | AL7: =AI7 -> 19133.622 | AM7: 360ONE | AN7: RF | AO7: =AL7 -> 19133.622 | AP7: TVSMOTOR | AQ7: F | AR7: =AO7 -> 19133.622 | AS7: ALKEM | AT7: RF | AU7: =AR7 -> 19133.622 | AV7: HAL | AW7: RF | AX7: =AU7 -> 19133.622 | AY7: COFORGE | AZ7: F
A8: 6 | B8: ='Trading Steps'!M17 -> 20250.279 | C8: EICHERMOT | E8: =B8 -> 20250.279 | F8: SCHAEFFLER | H8: =E8 -> 20250.279 | I8: PRESTIGE
